Workbook

Sheet 口算题
A1: 100以内加减法练习（30题）
A2: 姓名：____________ 日期：____________ 用时：______分 正确：______ / 30
A3: 刷新题目：按键盘 F9 键，一键更换全部 30 道题；打开本文件时也会自动出新题。
A5: 一、口算（20题）：不进退位 · 进退位 · 连加连减 · 填缺数
A6: =G26&" "&E26&" "&H26&" = " -> 66 + 12 = | C6: =G31&" "&E31&" "&H31&" = " -> 71 + 9 = | E6: =G36&" "&E36&" "&H36&" "&F36&" "&I36&" = " -> 34 + 26 + 21 = | H6: =IF(F41=1,"（ ） "&D41&" "&B41&" "&E41&" "&C41,IF(F41=2,A41&" "&D41&" （ ） "&E41&" "&C41,A41&" "&D41&" "&B41&" "&E41&" （ ）"))&" = "&G41 -> 23 + （ ） + 29 = 70
A7: =G27&" "&E27&" "&H27&" = " -> 96 - 60 = | C7: =G32&" "&E32&" "&H32&" = " -> 31 - 14 = | E7: =G37&" "&E37&" "&H37&" "&F37&" "&I37&" = " -> 84 - 31 - 31 = | H7: =IF(F42=1,"（ ） "&D42&" "&B42&" "&E42&" "&C42,IF(F42=2,A42&" "&D42&" （ ） "&E42&" "&C42,A42&" "&D42&" "&B42&" "&E42&" （ ）"))&" = "&G42 -> 77 - （ ） - 13 = 32
A8: =G28&" "&E28&" "&H28&" = " -> 11 + 7 = | C8: =G33&" "&E33&" "&H33&" = " -> 18 + 29 = | E8: =G38&" "&E38&" "&H38&" "&F38&" "&I38&" = " -> 50 + 25 - 30 = | H8: =IF(F43=1,"（ ） "&D43&" "&B43&" "&E43&" "&C43,IF(F43=2,A43&" "&D43&" （ ） "&E43&" "&C43,A43&" "&D43&" "&B43&" "&E43&" （ ）"))&" = "&G43 -> 13 + 74 - （ ） = 53
A9: =G29&" "&E29&" "&H29&" = " -> 34 - 23 = | C9: =G34&" "&E34&" "&H34&" = " -> 22 - 6 = | E9: =G39&" "&E39&" "&H39&" "&F39&" "&I39&" = " -> 69 - 15 + 17 = | H9: =IF(F44=1,"（ ） "&D44&" "&B44&" "&E44&" "&C44,IF(F44=2,A44&" "&D44&" （ ） "&E44&" "&C44,A44&" "&D44&" "&B44&" "&E44&" （ ）"))&" = "&G44 -> 86 - 45 + （ ） = 98
A10: =G30&" "&E30&" "&H30&" = " -> 75 + 11 = | C10: =G35&" "&E35&" "&H35&" = " -> 14 + 28 = | E10: =G40&" "&E40&" "&H40&" "&F40&" "&I40&" = " -> 70 - 40 + 29 = | H10: =IF(F45=1,"（ ） "&D45&" "&B45&" "&E45&" "&C45,IF(F45=2,A45&" "&D45&" （ ） "&E45&" "&C45,A45&" "&D45&" "&B45&" "&E45&" （ ）"))&" = "&G45 -> （ ） + 28 - 36 = 51
A12: 二、竖式计算（加减混合，5题）
A13: =G46 -> 46 | C13: =G47 -> 53 | E13: =G48 -> 80 | G13: =G49 -> 19 | I13: =G50 -> 30
A14: =E46&" "&H46 -> - 27 | C14: =E47&" "&H47 -> + 28 | E14: =E48&" "&H48 -> - 46 | G14: =E49&" "&H49 -> + 43 | I14: =E50&" "&H50 -> - 19
A17: 三、按规律填空和等量代换（5题）
A18: ="1、按规律填数："&A51&"、"&(A51+D51)&"、"&(A51+2*D51)&"、（ ）、"&(A51+4*D51) -> 1、按规律填数：3、12、21、（ ）、39
A19: =IF(J52=1,"2、找规律，接着画：● ○ ● ○ ● （ ）",IF(J52=2,"2、找规律，接着画：○ ● ○ ● ○ （ ）",IF(J52=3,"2、找规律，接着画：▲ ■ ▲ ■ ▲ （ ）","2、找规律，接着画：● ● ○ ● ● ○ ● （ ）"))) -> 2、找规律，接着画：● ● ○ ● ● ○ ● （ ）
A20: ="3、1个西瓜 = "&A53&"个苹果，1个苹果 = "&B53&"个桃子，1个西瓜 =（ ）个桃子" -> 3、1个西瓜 = 3个苹果，1个苹果 = 4个桃子，1个西瓜 =（ ）个桃子
A21: ="4、△ + △ + △ = "&(3*A54)&"，△ =（ ）" -> 4、△ + △ + △ = 24，△ =（ ）
A22: ="5、△ + ○ = "&A55&"，△ = "&B55&"，○ =（ ）" -> 5、△ + ○ = 15，△ = 6，○ =（ ）
A24: 答案见“答案”工作表。
A26: =RANDBETWEEN(1,8) -> 6 | B26: =RANDBETWEEN(0,8) -> 6 | C26: =RANDBETWEEN(0,9-A26) -> 1 | D26: =IF(C26=0,RANDBETWEEN(1,9-B26),RANDBETWEEN(0,9-B26)) -> 2 | E26: + | G26: =A26*10+B26 -> 66 | H26: =C26*10+D26 -> 12
A27: =RANDBETWEEN(1,9) -> 9 | B27: =RANDBETWEEN(1,9) -> 6 | C27: =RANDBETWEEN(0,A27-1) -> 6 | D27: =IF(C27=0,RANDBETWEEN(1,B27),RANDBETWEEN(0,B27)) -> 0 | E27: - | G27: =A27*10+B27 -> 96 | H27: =C27*10+D27 -> 60
A28: =RANDBETWEEN(1,8) -> 1 | B28: =RANDBETWEEN(0,8) -> 1 | C28: =RANDBETWEEN(0,9-A28) -> 0 | D28: =IF(C28=0,RANDBETWEEN(1,9-B28),RANDBETWEEN(0,9-B28)) -> 7 | E28: + | G28: =A28*10+B28 -> 11 | H28: =C28*10+D28 -> 7
A29: =RANDBETWEEN(1,9) -> 3 | B29: =RANDBETWEEN(1,9) -> 4 | C29: =RANDBETWEEN(0,A29-1) -> 2 | D29: =IF(C29=0,RANDBETWEEN(1,B29),RANDBETWEEN(0,B29)) -> 3 | E29: - | G29: =A29*10+B29 -> 34 | H29: =C29*10+D29 -> 23
A30: =RANDBETWEEN(1,8) -> 7 | B30: =RANDBETWEEN(0,8) -> 5 | C30: =RANDBETWEEN(0,9-A30) -> 1 | D30: =IF(C30=0,RANDBETWEEN(1,9-B30),RANDBETWEEN(0,9-B30)) -> 1 | E30: + | G30: =A30*10+B30 -> 75 | H30: =C30*10+D30 -> 11
A31: =RANDBETWEEN(1,8) -> 7 | B31: =RANDBETWEEN(1,9) -> 1 | C31: =RANDBETWEEN(0,8-A31) -> 0 | D31: =RANDBETWEEN(10-B31,9) -> 9 | E31: + | G31: =A31*10+B31 -> 71 | H31: =C31*10+D31 -> 9
A32: =RANDBETWEEN(2,9) -> 3 | B32: =RANDBETWEEN(0,8) -> 1 | C32: =RANDBETWEEN(0,A32-2) -> 1 | D32: =RANDBETWEEN(B32+1,9) -> 4 | E32: - | G32: =A32*10+B32 -> 31 | H32: =C32*10+D32 -> 14
A33: =RANDBETWEEN(1,8) -> 1 | B33: =RANDBETWEEN(1,9) -> 8 | C33: =RANDBETWEEN(0,8-A33) -> 2 | D33: =RANDBETWEEN(10-B33,9) -> 9 | E33: + | G33: =A33*10+B33 -> 18 | H33: =C33*10+D33 -> 29
A34: =RANDBETWEEN(2,9) -> 2 | B34: =RANDBETWEEN(0,8) -> 2 | C34: =RANDBETWEEN(0,A34-2) -> 0 | D34: =RANDBETWEEN(B34+1,9) -> 6 | E34: - | G34: =A34*10+B34 -> 22 | H34: =C34*10+D34 -> 6
A35: =RANDBETWEEN(1,8) -> 1 | B35: =RANDBETWEEN(1,9) -> 4 | C35: =RANDBETWEEN(0,8-A35) -> 2 | D35: =RANDBETWEEN(10-B35,9) -> 8 | E35: + | G35: =A35*10+B35 -> 14 | H35: =C35*10+D35 -> 28
E36: + | F36: + | G36: =RANDBETWEEN(10,50) -> 34 | H36: =RANDBETWEEN(10,90-G36) -> 26 | I36: =RANDBETWEEN(10,100-G36-H36) -> 21
E37: - | F37: - | G37: =RANDBETWEEN(40,99) -> 84 | H37: =RANDBETWEEN(10,G37-20) -> 31 | I37: =RANDBETWEEN(10,G37-H37-10) -> 31
E38: + | F38: - | G38: =RANDBETWEEN(10,60) -> 50 | H38: =RANDBETWEEN(10,90-G38) -> 25 | I38: =RANDBETWEEN(10,G38+H38-10) -> 30
E39: - | F39: + | G39: =RANDBETWEEN(40,90) -> 69 | H39: =RANDBETWEEN(10,G39-10) -> 15 | I39: =RANDBETWEEN(10,100-(G39-H39)) -> 17
E40: =IF(J40=1,"+","-") -> - | F40: =IF(J40=1,"-","+") -> + | G40: =IF(J40=1,RANDBETWEEN(10,60),RANDBETWEEN(40,90)) -> 70 | H40: =IF(J40=1,RANDBETWEEN(10,90-G40),RANDBETWEEN(10,G40-10)) -> 40 | I40: =IF(J40=1,RANDBETWEEN(10,G40+H40-10),RANDBETWEEN(10,100-(G40-H40))) -> 29 | J40: =RANDBETWEEN(1,2) -> 2
A41: =RANDBETWEEN(10,45) -> 23 | B41: =RANDBETWEEN(10,44) -> 18 | C41: =RANDBETWEEN(10,99-A41-B41) -> 29 | D41: + | E41: + | F41: 2 | G41: =A41+B41+C41 -> 70
A42: =RANDBETWEEN(60,99) -> 77 | B42: =RANDBETWEEN(10,A42-30) -> 32 | C42: =RANDBETWEEN(10,A42-B42-10) -> 13 | D42: - | E42: - | F42: 2 | G42: =A42-B42-C42 -> 32
A43: =RANDBETWEEN(10,50) -> 13 | B43: =RANDBETWEEN(10,90-A43) -> 74 | C43: =A43+B43-RANDBETWEEN(10,A43+B43-10) -> 34 | D43: + | E43: - | F43: 3 | G43: =A43+B43-C43 -> 53
A44: =RANDBETWEEN(50,90) -> 86 | B44: =RANDBETWEEN(10,A44-20) -> 45 | C44: =RANDBETWEEN(A44-B44+10,99)-(A44-B44) -> 57 | D44: - | E44: + | F44: 3 | G44: =A44-B44+C44 -> 98
A45: =RANDBETWEEN(30,80) -> 59 | B45: =RANDBETWEEN(10,100-A45) -> 28 | C45: =RANDBETWEEN(10,A45-20) -> 36 | D45: + | E45: - | F45: 1 | G45: =A45+B45-C45 -> 51
A46: =RANDBETWEEN(3,9) -> 4 | B46: =RANDBETWEEN(0,8) -> 6 | C46: =RANDBETWEEN(1,A46-2) -> 2 | D46: =RANDBETWEEN(B46+1,9) -> 7 | E46: - | G46: =A46*10+B46 -> 46 | H46: =C46*10+D46 -> 27
...

Sheet 答案
A1: 100以内加减法练习 · 答案
A2: 批改日期：____________ 正确：______ / 30
A3: 答案页：口算给结果，竖式给得数，第三部分括号内为所填的数。
A5: 一、口算（20题）：不进退位 · 进退位 · 连加连减 · 填缺数
A6: =口算题!G26&" "&口算题!E26&" "&口算题!H26&" = "&IF(口算题!E26="+",口算题!G26+口算题!H26,口算题!G26-口算题!H26) -> 66 + 12 = 78 | C6: =口算题!G31&" "&口算题!E31&" "&口算题!H31&" = "&IF(口算题!E31="+",口算题!G31+口算题!H31,口算题!G31-口算题!H31) -> 71 + 9 = 80 | E6: =口算题!G36&" "&口算题!E36&" "&口算题!H36&" "&口算题!F36&" "&口算题!I36&" = "&IF(口算题!F36="+",IF(口算题!E36="+",口算题!G36+口算题!H36,口算题!G36-口算题!H36)+口算题!I36,IF(口算题!E36="+",口算题!G36+口算题!H36,口算题!G36-口算题!H36)-口算题!I36) -> 34 + 26 + 21 = 81 | H6: =IF(口算题!F41=1,"（"&口算题!A41&"） "&口算题!D41&" "&口算题!B41&" "&口算题!E41&" "&口算题!C41,IF(口算题!F41=2,口算题!A41&" "&口算题!D41&" （"&口算题!B41&"） "&口算题!E41&" "&口算题!C41,口算题!A41&" "&口算题!D41&" "&口算题!B41&" "&口算题!E41&" （"&口算题!C41&"）"))&" = "&口算题!G41 -> 23 + （18） + 29 = 70
A7: =口算题!G27&" "&口算题!E27&" "&口算题!H27&" = "&IF(口算题!E27="+",口算题!G27+口算题!H27,口算题!G27-口算题!H27) -> 96 - 60 = 36 | C7: =口算题!G32&" "&口算题!E32&" "&口算题!H32&" = "&IF(口算题!E32="+",口算题!G32+口算题!H32,口算题!G32-口算题!H32) -> 31 - 14 = 17 | E7: =口算题!G37&" "&口算题!E37&" "&口算题!H37&" "&口算题!F37&" "&口算题!I37&" = "&IF(口算题!F37="+",IF(口算题!E37="+",口算题!G37+口算题!H37,口算题!G37-口算题!H37)+口算题!I37,IF(口算题!E37="+",口算题!G37+口算题!H37,口算题!G37-口算题!H37)-口算题!I37) -> 84 - 31 - 31 = 22 | H7: =IF(口算题!F42=1,"（"&口算题!A42&"） "&口算题!D42&" "&口算题!B42&" "&口算题!E42&" "&口算题!C42,IF(口算题!F42=2,口算题!A42&" "&口算题!D42&" （"&口算题!B42&"） "&口算题!E42&" "&口算题!C42,口算题!A42&" "&口算题!D42&" "&口算题!B42&" "&口算题!E42&" （"&口算题!C42&"）"))&" = "&口算题!G42 -> 77 - （32） - 13 = 32
A8: =口算题!G28&" "&口算题!E28&" "&口算题!H28&" = "&IF(口算题!E28="+",口算题!G28+口算题!H28,口算题!G28-口算题!H28) -> 11 + 7 = 18 | C8: =口算题!G33&" "&口算题!E33&" "&口算题!H33&" = "&IF(口算题!E33="+",口算题!G33+口算题!H33,口算题!G33-口算题!H33) -> 18 + 29 = 47 | E8: =口算题!G38&" "&口算题!E38&" "&口算题!H38&" "&口算题!F38&" "&口算题!I38&" = "&IF(口算题!F38="+",IF(口算题!E38="+",口算题!G38+口算题!H38,口算题!G38-口算题!H38)+口算题!I38,IF(口算题!E38="+",口算题!G38+口算题!H38,口算题!G38-口算题!H38)-口算题!I38) -> 50 + 25 - 30 = 45 | H8: =IF(口算题!F43=1,"（"&口算题!A43&"） "&口算题!D43&" "&口算题!B43&" "&口算题!E43&" "&口算题!C43,IF(口算题!F43=2,口算题!A43&" "&口算题!D43&" （"&口算题!B43&"） "&口算题!E43&" "&口算题!C43,口算题!A43&" "&口算题!D43&" "&口算题!B43&" "&口算题!E43&" （"&口算题!C43&"）"))&" = "&口算题!G43 -> 13 + 74 - （34） = 53
A9: =口算题!G29&" "&口算题!E29&" "&口算题!H29&" = "&IF(口算题!E29="+",口算题!G29+口算题!H29,口算题!G29-口算题!H29) -> 34 - 23 = 11 | C9: =口算题!G34&" "&口算题!E34&" "&口算题!H34&" = "&IF(口算题!E34="+",口算题!G34+口算题!H34,口算题!G34-口算题!H34) -> 22 - 6 = 16 | E9: =口算题!G39&" "&口算题!E39&" "&口算题!H39&" "&口算题!F39&" "&口算题!I39&" = "&IF(口算题!F39="+",IF(口算题!E39="+",口算题!G39+口算题!H39,口算题!G39-口算题!H39)+口算题!I39,IF(口算题!E39="+",口算题!G39+口算题!H39,口算题!G39-口算题!H39)-口算题!I39) -> 69 - 15 + 17 = 71 | H9: =IF(口算题!F44=1,"（"&口算题!A44&"） "&口算题!D44&" "&口算题!B44&" "&口算题!E44&" "&口算题!C44,IF(口算题!F44=2,口算题!A44&" "&口算题!D44&" （"&口算题!B44&"） "&口算题!E44&" "&口算题!C44,口算题!A44&" "&口算题!D44&" "&口算题!B44&" "&口算题!E44&" （"&口算题!C44&"）"))&" = "&口算题!G44 -> 86 - 45 + （57） = 98
A10: =口算题!G30&" "&口算题!E30&" "&口算题!H30&" = "&IF(口算题!E30="+",口算题!G30+口算题!H30,口算题!G30-口算题!H30) -> 75 + 11 = 86 | C10: =口算题!G35&" "&口算题!E35&" "&口算题!H35&" = "&IF(口算题!E35="+",口算题!G35+口算题!H35,口算题!G35-口算题!H35) -> 14 + 28 = 42 | E10: =口算题!G40&" "&口算题!E40&" "&口算题!H40&" "&口算题!F40&" "&口算题!I40&" = "&IF(口算题!F40="+",IF(口算题!E40="+",口算题!G40+口算题!H40,口算题!G40-口算题!H40)+口算题!I40,IF(口算题!E40="+",口算题!G40+口算题!H40,口算题!G40-口算题!H40)-口算题!I40) -> 70 - 40 + 29 = 59 | H10: =IF(口算题!F45=1,"（"&口算题!A45&"） "&口算题!D45&" "&口算题!B45&" "&口算题!E45&" "&口算题!C45,IF(口算题!F45=2,口算题!A45&" "&口算题!D45&" （"&口算题!B45&"） "&口算题!E45&" "&口算题!C45,口算题!A45&" "&口算题!D45&" "&口算题!B45&" "&口算题!E45&" （"&口算题!C45&"）"))&" = "&口算题!G45 -> （59） + 28 - 36 = 51
A12: 二、竖式计算（加减混合，5题）
A13: =口算题!G46 -> 46 | C13: =口算题!G47 -> 53 | E13: =口算题!G48 -> 80 | G13: =口算题!G49 -> 19 | I13: =口算题!G50 -> 30
A14: =口算题!E46&" "&口算题!H46 -> - 27 | C14: =口算题!E47&" "&口算题!H47 -> + 28 | E14: =口算题!E48&" "&口算题!H48 -> - 46 | G14: =口算题!E49&" "&口算题!H49 -> + 43 | I14: =口算题!E50&" "&口算题!H50 -> - 19
A15: =IF(口算题!E46="+",口算题!G46+口算题!H46,口算题!G46-口算题!H46) -> 19 | C15: =IF(口算题!E47="+",口算题!G47+口算题!H47,口算题!G47-口算题!H47) -> 81 | E15: =IF(口算题!E48="+",口算题!G48+口算题!H48,口算题!G48-口算题!H48) -> 34 | G15: =IF(口算题!E49="+",口算题!G49+口算题!H49,口算题!G49-口算题!H49) -> 62 | I15: =IF(口算题!E50="+",口算题!G50+口算题!H50,口算题!G50-口算题!H50) -> 11
A17: 三、按规律填空和等量代换（5题）
A18: ="1、按规律填数："&口算题!A51&"、"&(口算题!A51+口算题!D51)&"、"&(口算题!A51+2*口算题!D51)&"、（"&(口算题!A51+3*口算题!D51)&"）、"&(口算题!A51+4*口算题!D51) -> 1、按规律填数：3、12、21、（30）、39
A19: =IF(口算题!J52=1,"2、找规律，接着画：● ○ ● ○ ● （○）",IF(口算题!J52=2,"2、找规律，接着画：○ ● ○ ● ○ （●）",IF(口算题!J52=3,"2、找规律，接着画：▲ ■ ▲ ■ ▲ （■）","2、找规律，接着画：● ● ○ ● ● ○ ● （●）"))) -> 2、找规律，接着画：● ● ○ ● ● ○ ● （●）
A20: ="3、1个西瓜 = "&口算题!A53&"个苹果，1个苹果 = "&口算题!B53&"个桃子，1个西瓜 =（"&(口算题!A53*口算题!B53)&"）个桃子" -> 3、1个西瓜 = 3个苹果，1个苹果 = 4个桃子，1个西瓜 =（12）个桃子
A21: ="4、△ + △ + △ = "&(3*口算题!A54)&"，△ =（"&口算题!A54&"）" -> 4、△ + △ + △ = 24，△ =（8）
A22: ="5、△ + ○ = "&口算题!A55&"，△ = "&口算题!B55&"，○ =（"&(口算题!A55-口算题!B55)&"）" -> 5、△ + ○ = 15，△ = 6，○ =（9）
A24: 答案页：括号内为所填的数，竖式下方为得数。
